Workbook
Name RICK_and_MORTY_BAD_TRIP: #REF!
Name RICK_and_MORTY_BAD_ACID: #REF!

Sheet Лист1
A1: Номер | B1: Дата | C1: Время | D1: Позиция | E1: Коменты | F1: Скидка | G1: Чистый заработок за день | H1: Выручка | I1: Розничная цена | J1: Закупочная цена | K1: Прибыль с единицы
A4: 1 | B4: 45951 | C4: 0.57466435 | D4: RICK and MORTY BAD ACID | G4: =SUM(K4:K63) -> 269.2 | H4: =SUM(J4:K63) -> 622 | I4: {=IF(D4="","",INDEX('Товары '!$D$2:$D$78, MATCH(D4, 'Товары '!$B$2:$B$78, 0)))} -> 15 | J4: =IF(D4="","",VLOOKUP(D4, 'Товары '!$B$2:$C$78, 2, FALSE)) -> 9 | K4: =IF(OR(I4="", J4=""), "", VALUE(I4) - VALUE(J4))-F4 -> 6
A5: 2 | B5: 45951 | C5: 0.57469907 | D5: Катриджи Vaporesso XROS | I5: {=IF(D5="","",INDEX('Товары '!$D$2:$D$78, MATCH(D5, 'Товары '!$B$2:$B$78, 0)))} -> 13 | J5: =IF(D5="","",VLOOKUP(D5, 'Товары '!$B$2:$C$78, 2, FALSE)) -> 6.4 | K5: =IF(OR(I5="", J5=""), "", VALUE(I5) - VALUE(J5))-F5 -> 6.6
A6: 3 | B6: 45951 | C6: 0.57991898 | D6: Катриджи Vaporesso XROS | I6: {=IF(D6="","",INDEX('Товары '!$D$2:$D$78, MATCH(D6, 'Товары '!$B$2:$B$78, 0)))} -> 13 | J6: =IF(D6="","",VLOOKUP(D6, 'Товары '!$B$2:$C$78, 2, FALSE)) -> 6.4 | K6: =IF(OR(I6="", J6=""), "", VALUE(I6) - VALUE(J6))-F6 -> 6.6
A7: 4 | B7: 45951 | C7: 0.5843287 | D7: Xros 5 мини | I7: {=IF(D7="","",INDEX('Товары '!$D$2:$D$78, MATCH(D7, 'Товары '!$B$2:$B$78, 0)))} -> 70 | J7: =IF(D7="","",VLOOKUP(D7, 'Товары '!$B$2:$C$78, 2, FALSE)) -> 40 | K7: =IF(OR(I7="", J7=""), "", VALUE(I7) - VALUE(J7))-F7 -> 30
A8: 5 | B8: 45951 | C8: 0.58443287 | D8: CATSWILL (кислые | I8: {=IF(D8="","",INDEX('Товары '!$D$2:$D$78, MATCH(D8, 'Товары '!$B$2:$B$78, 0)))} -> 15 | J8: =IF(D8="","",VLOOKUP(D8, 'Товары '!$B$2:$C$78, 2, FALSE)) -> 9 | K8: =IF(OR(I8="", J8=""), "", VALUE(I8) - VALUE(J8))-F8 -> 6
A9: 6 | B9: 45951 | C9: 0.59041667 | D9: Катриджи Vaporesso XROS | I9: {=IF(D9="","",INDEX('Товары '!$D$2:$D$78, MATCH(D9, 'Товары '!$B$2:$B$78, 0)))} -> 13 | J9: =IF(D9="","",VLOOKUP(D9, 'Товары '!$B$2:$C$78, 2, FALSE)) -> 6.4 | K9: =IF(OR(I9="", J9=""), "", VALUE(I9) - VALUE(J9))-F9 -> 6.6
A10: 7 | B10: 45951 | C10: 0.59288194 | D10: RICK and MORTY BAD TRIP | I10: {=IF(D10="","",INDEX('Товары '!$D$2:$D$78, MATCH(D10, 'Товары '!$B$2:$B$78, 0)))} -> 15 | J10: =IF(D10="","",VLOOKUP(D10, 'Товары '!$B$2:$C$78, 2, FALSE)) -> 9 | K10: =IF(OR(I10="", J10=""), "", VALUE(I10) - VALUE(J10))-F10 -> 6
A11: 8 | B11: 45951 | C11: 0.59491898 | D11: RICK and MORTY BAD TRIP | I11: {=IF(D11="","",INDEX('Товары '!$D$2:$D$78, MATCH(D11, 'Товары '!$B$2:$B$78, 0)))} -> 15 | J11: =IF(D11="","",VLOOKUP(D11, 'Товары '!$B$2:$C$78, 2, FALSE)) -> 9 | K11: =IF(OR(I11="", J11=""), "", VALUE(I11) - VALUE(J11))-F11 -> 6
A12: 9 | B12: 45951 | D12: Катриджи Vaporesso XROS | I12: {=IF(D12="","",INDEX('Товары '!$D$2:$D$78, MATCH(D12, 'Товары '!$B$2:$B$78, 0)))} -> 13 | J12: =IF(D12="","",VLOOKUP(D12, 'Товары '!$B$2:$C$78, 2, FALSE)) -> 6.4 | K12: =IF(OR(I12="", J12=""), "", VALUE(I12) - VALUE(J12))-F12 -> 6.6
A13: 10 | B13: 45951 | D13: Катриджи Vaporesso XROS | F13: 1 | I13: {=IF(D13="","",INDEX('Товары '!$D$2:$D$78, MATCH(D13, 'Товары '!$B$2:$B$78, 0)))} -> 13 | J13: =IF(D13="","",VLOOKUP(D13, 'Товары '!$B$2:$C$78, 2, FALSE)) -> 6.4 | K13: =IF(OR(I13="", J13=""), "", VALUE(I13) - VALUE(J13))-F13 -> 5.6
A14: 11 | B14: 45951 | C14: 0.61070602 | D14: PODONKI LAST HAP | I14: {=IF(D14="","",INDEX('Товары '!$D$2:$D$78, MATCH(D14, 'Товары '!$B$2:$B$78, 0)))} -> 15 | J14: =IF(D14="","",VLOOKUP(D14, 'Товары '!$B$2:$C$78, 2, FALSE)) -> 8.5 | K14: =IF(OR(I14="", J14=""), "", VALUE(I14) - VALUE(J14))-F14 -> 6.5
A15: 12 | B15: 45951 | C15: 0.61423611 | D15: Катриджи Vaporesso XROS | I15: {=IF(D15="","",INDEX('Товары '!$D$2:$D$78, MATCH(D15, 'Товары '!$B$2:$B$78, 0)))} -> 13 | J15: =IF(D15="","",VLOOKUP(D15, 'Товары '!$B$2:$C$78, 2, FALSE)) -> 6.4 | K15: =IF(OR(I15="", J15=""), "", VALUE(I15) - VALUE(J15))-F15 -> 6.6
A16: 13 | B16: 45951 | C16: 0.64548611 | D16: CATSWILL (кислые | I16: {=IF(D16="","",INDEX('Товары '!$D$2:$D$78, MATCH(D16, 'Товары '!$B$2:$B$78, 0)))} -> 15 | J16: =IF(D16="","",VLOOKUP(D16, 'Товары '!$B$2:$C$78, 2, FALSE)) -> 9 | K16: =IF(OR(I16="", J16=""), "", VALUE(I16) - VALUE(J16))-F16 -> 6
A17: 14 | B17: 45951 | C17: 0.67211806 | D17: Катриджи Vaporesso XROS | I17: {=IF(D17="","",INDEX('Товары '!$D$2:$D$78, MATCH(D17, 'Товары '!$B$2:$B$78, 0)))} -> 13 | J17: =IF(D17="","",VLOOKUP(D17, 'Товары '!$B$2:$C$78, 2, FALSE)) -> 6.4 | K17: =IF(OR(I17="", J17=""), "", VALUE(I17) - VALUE(J17))-F17 -> 6.6
A18: 15 | B18: 45951 | C18: 0.70815972 | D18: Катриджи Vaporesso XROS | I18: {=IF(D18="","",INDEX('Товары '!$D$2:$D$78, MATCH(D18, 'Товары '!$B$2:$B$78, 0)))} -> 13 | J18: =IF(D18="","",VLOOKUP(D18, 'Товары '!$B$2:$C$78, 2, FALSE)) -> 6.4 | K18: =IF(OR(I18="", J18=""), "", VALUE(I18) - VALUE(J18))-F18 -> 6.6
A19: 16 | B19: 45951 | C19: 0.7081713 | D19: RICK AND MORTY BAD ICE | I19: {=IF(D19="","",INDEX('Товары '!$D$2:$D$78, MATCH(D19, 'Товары '!$B$2:$B$78, 0)))} -> 15 | J19: =IF(D19="","",VLOOKUP(D19, 'Товары '!$B$2:$C$78, 2, FALSE)) -> 9 | K19: =IF(OR(I19="", J19=""), "", VALUE(I19) - VALUE(J19))-F19 -> 6
A20: 17 | B20: 45951 | C20: 0.7359375 | D20: RICK and MORTY BAD TRIP | I20: {=IF(D20="","",INDEX('Товары '!$D$2:$D$78, MATCH(D20, 'Товары '!$B$2:$B$78, 0)))} -> 15 | J20: =IF(D20="","",VLOOKUP(D20, 'Товары '!$B$2:$C$78, 2, FALSE)) -> 9 | K20: =IF(OR(I20="", J20=""), "", VALUE(I20) - VALUE(J20))-F20 -> 6
A21: 18 | B21: 45951 | C21: 0.73615741 | D21: Podonk Critical | I21: {=IF(D21="","",INDEX('Товары '!$D$2:$D$78, MATCH(D21, 'Товары '!$B$2:$B$78, 0)))} -> 15 | J21: =IF(D21="","",VLOOKUP(D21, 'Товары '!$B$2:$C$78, 2, FALSE)) -> 8 | K21: =IF(OR(I21="", J21=""), "", VALUE(I21) - VALUE(J21))-F21 -> 7
A22: 19 | B22: 45951 | C22: 0.74640046 | D22: RICK and MORTY BAD TRIP | I22: {=IF(D22="","",INDEX('Товары '!$D$2:$D$78, MATCH(D22, 'Товары '!$B$2:$B$78, 0)))} -> 15 | J22: =IF(D22="","",VLOOKUP(D22, 'Товары '!$B$2:$C$78, 2, FALSE)) -> 9 | K22: =IF(OR(I22="", J22=""), "", VALUE(I22) - VALUE(J22))-F22 -> 6
A23: 20 | B23: 45951 | C23: 0.73841435 | D23: Катриджи Vaporesso XROS | I23: {=IF(D23="","",INDEX('Товары '!$D$2:$D$78, MATCH(D23, 'Товары '!$B$2:$B$78, 0)))} -> 13 | J23: =IF(D23="","",VLOOKUP(D23, 'Товары '!$B$2:$C$78, 2, FALSE)) -> 6.4 | K23: =IF(OR(I23="", J23=""), "", VALUE(I23) - VALUE(J23))-F23 -> 6.6
A24: 21 | B24: 45951 | C24: 0.73872685 | D24: Geek vape | I24: {=IF(D24="","",INDEX('Товары '!$D$2:$D$78, MATCH(D24, 'Товары '!$B$2:$B$78, 0)))} -> 13 | J24: =IF(D24="","",VLOOKUP(D24, 'Товары '!$B$2:$C$78, 2, FALSE)) -> 6.4 | K24: =IF(OR(I24="", J24=""), "", VALUE(I24) - VALUE(J24))-F24 -> 6.6
A25: 22 | B25: 45951 | C25: 0.74519676 | D25: Самоубийца V2 | I25: {=IF(D25="","",INDEX('Товары '!$D$2:$D$78, MATCH(D25, 'Товары '!$B$2:$B$78, 0)))} -> 15 | J25: =IF(D25="","",VLOOKUP(D25, 'Товары '!$B$2:$C$78, 2, FALSE)) -> 9 | K25: =IF(OR(I25="", J25=""), "", VALUE(I25) - VALUE(J25))-F25 -> 6
... A33: 30 | B33: 45951 | C33: 0.79703704 | D33: RICK and MORTY BAD ACID | I33: {=IF(D33="","",INDEX('Товары '!$D$2:$D$78, MATCH(D33, 'Товары '!$B$2:$B$78, 0)))} -> 15 | J33: =IF(D33="","",VLOOKUP(D33, 'Товары '!$B$2:$C$78, 2, FALSE)) -> 9 | K33: =IF(OR(I33="", J33=""), "", VALUE(I33) - VALUE(J33))-F33 -> 6
A34: 31 | B34: 45951 | C34: 0.79894676 | D34: Xros 5 мини | F34: 5 | I34: {=IF(D34="","",INDEX('Товары '!$D$2:$D$78, MATCH(D34, 'Товары '!$B$2:$B$78, 0)))} -> 70 | J34: =IF(D34="","",VLOOKUP(D34, 'Товары '!$B$2:$C$78, 2, FALSE)) -> 40 | K34: =IF(OR(I34="", J34=""), "", VALUE(I34) - VALUE(J34))-F34 -> 25
A35: 32 | B35: 45951 | C35: 0.82726852 | D35: RICK AND MORTY BAD ICE | I35: {=IF(D35="","",INDEX('Товары '!$D$2:$D$78, MATCH(D35, 'Товары '!$B$2:$B$78, 0)))} -> 15 | J35: =IF(D35="","",VLOOKUP(D35, 'Товары '!$B$2:$C$78, 2, FALSE)) -> 9 | K35: =IF(OR(I35="", J35=""), "", VALUE(I35) - VALUE(J35))-F35 -> 6
A36: 33 | B36: 45951 | C36: 0.82726852 | D36: RICK AND MORTY BAD ICE | I36: {=IF(D36="","",INDEX('Товары '!$D$2:$D$78, MATCH(D36, 'Товары '!$B$2:$B$78, 0)))} -> 15 | J36: =IF(D36="","",VLOOKUP(D36, 'Товары '!$B$2:$C$78, 2, FALSE)) -> 9 | K36: =IF(OR(I36="", J36=""), "", VALUE(I36) - VALUE(J36))-F36 -> 6
A37: 34 | B37: 45951 | C37: 0.8621412 | D37: Катриджи Vaporesso XROS | I37: {=IF(D37="","",INDEX('Товары '!$D$2:$D$78, MATCH(D37, 'Товары '!$B$2:$B$78, 0)))} -> 13 | J37: =IF(D37="","",VLOOKUP(D37, 'Товары '!$B$2:$C$78, 2, FALSE)) -> 6.4 | K37: =IF(OR(I37="", J37=""), "", VALUE(I37) - VALUE(J37))-F37 -> 6.6
A38: 35 | B38: 45951 | C38: 0.88949074 | D38: CATSWILL (кислые | I38: {=IF(D38="","",INDEX('Товары '!$D$2:$D$78, MATCH(D38, 'Товары '!$B$2:$B$78, 0)))} -> 15 | J38: =IF(D38="","",VLOOKUP(D38, 'Товары '!$B$2:$C$78, 2, FALSE)) -> 9 | K38: =IF(OR(I38="", J38=""), "", VALUE(I38) - VALUE(J38))-F38 -> 6
A39: 36 | B39: 45951 | C39: 0.88952546 | D39: CATSWILL (кислые | I39: {=IF(D39="","",INDEX('Товары '!$D$2:$D$78, MATCH(D39, 'Товары '!$B$2:$B$78, 0)))} -> 15 | J39: =IF(D39="","",VLOOKUP(D39, 'Товары '!$B$2:$C$78, 2, FALSE)) -> 9 | K39: =IF(OR(I39="", J39=""), "", VALUE(I39) - VALUE(J39))-F39 -> 6
A40: 37 | I40: {=IF(D40="","",INDEX('Товары '!$D$2:$D$78, MATCH(D40, 'Товары '!$B$2:$B$78, 0)))} | J40: =IF(D40="","",VLOOKUP(D40, 'Товары '!$B$2:$C$78, 2, FALSE)) | K40: =IF(OR(I40="", J40=""), "", VALUE(I40) - VALUE(J40))-F40 -> 0
A41: 38 | I41: {=IF(D41="","",INDEX('Товары '!$D$2:$D$78, MATCH(D41, 'Товары '!$B$2:$B$78, 0)))} | J41: =IF(D41="","",VLOOKUP(D41, 'Товары '!$B$2:$C$78, 2, FALSE)) | K41: =IF(OR(I41="", J41=""), "", VALUE(I41) - VALUE(J41))-F41 -> 0
A42: 39 | I42: {=IF(D42="","",INDEX('Товары '!$D$2:$D$78, MATCH(D42, 'Товары '!$B$2:$B$78, 0)))} | J42: =IF(D42="","",VLOOKUP(D42, 'Товары '!$B$2:$C$78, 2, FALSE)) | K42: =IF(OR(I42="", J42=""), "", VALUE(I42) - VALUE(J42))-F42 -> 0
A43: 40 | I43: {=IF(D43="","",INDEX('Товары '!$D$2:$D$78, MATCH(D43, 'Товары '!$B$2:$B$78, 0)))} | J43: =IF(D43="","",VLOOKUP(D43, 'Товары '!$B$2:$C$78, 2, FALSE)) | K43: =IF(OR(I43="", J43=""), "", VALUE(I43) - VALUE(J43))-F43 -> 0
A44: 41 | I44: {=IF(D44="","",INDEX('Товары '!$D$2:$D$78, MATCH(D44, 'Товары '!$B$2:$B$78, 0)))} | J44: =IF(D44="","",VLOOKUP(D44, 'Товары '!$B$2:$C$78, 2, FALSE)) | K44: =IF(OR(I44="", J44=""), "", VALUE(I44) - VALUE(J44))-F44 -> 0
A45: 42 | I45: {=IF(D45="","",INDEX('Товары '!$D$2:$D$78, MATCH(D45, 'Товары '!$B$2:$B$78, 0)))} | J45: =IF(D45="","",VLOOKUP(D45, 'Товары '!$B$2:$C$78, 2, FALSE)) | K45: =IF(OR(I45="", J45=""), "", VALUE(I45) - VALUE(J45))-F45 -> 0
A46: 43 | I46: {=IF(D46="","",INDEX('Товары '!$D$2:$D$78, MATCH(D46, 'Товары '!$B$2:$B$78, 0)))} | J46: =IF(D46="","",VLOOKUP(D46, 'Товары '!$B$2:$C$78, 2, FALSE)) | K46: =IF(OR(I46="", J46=""), "", VALUE(I46) - VALUE(J46))-F46 -> 0
A47: 44 | I47: {=IF(D47="","",INDEX('Товары '!$D$2:$D$78, MATCH(D47, 'Товары '!$B$2:$B$78, 0)))} | J47: =IF(D47="","",VLOOKUP(D47, 'Товары '!$B$2:$C$78, 2, FALSE)) | K47: =IF(OR(I47="", J47=""), "", VALUE(I47) - VALUE(J47))-F47 -> 0
A48: 45 | I48: {=IF(D48="","",INDEX('Товары '!$D$2:$D$78, MATCH(D48, 'Товары '!$B$2:$B$78, 0)))} | J48: =IF(D48="","",VLOOKUP(D48, 'Товары '!$B$2:$C$78, 2, FALSE)) | K48: =IF(OR(I48="", J48=""), "", VALUE(I48) - VALUE(J48))-F48 -> 0
A49: 46 | I49: {=IF(D49="","",INDEX('Товары '!$D$2:$D$78, MATCH(D49, 'Товары '!$B$2:$B$78, 0)))} | J49: =IF(D49="","",VLOOKUP(D49, 'Товары '!$B$2:$C$78, 2, FALSE)) | K49: =IF(OR(I49="", J49=""), "", VALUE(I49) - VALUE(J49))-F49 -> 0
...

Sheet Лист8

Sheet Лист6
A1: =IFERROR(__xludf.DUMMYFUNCTION("LET( _d, 'Днные'!A1:D5136, _b, 'Лист1'!D:D, _u, 2, _rows,IF(COUNTA(CHOOSECOLS(_b,_u-1))=0,0,LAMBDA(_e,COUNTIF(_e,""<""&MAX(_e))+1)(SCAN(0,CHOOSECOLS(_b,_u-1),LAMBDA(_a1,_b1, IF(_b1<>"""", _a1+1,_a1))))), _a,UNIQUE(MAKEARRAY(1,COLUMNS(_d),LAMBDA"&"(_x,_y,SCAN(,CHOOSECOLS(_d,_y),LAMBDA(_k,_m,IF(_m="""",_k,_m)))))), _r, MAKEARRAY(_rows,1,LAMBDA(_x,_y, TRANSPOSE(UNIQUE(IFERROR(FILTER(CHOOSECOLS(_a,_u),CHOOSECOLS(_a,_u-1)=INDEX(_b,_x,_u-1))))))), _r )"),"")
A4: =IFERROR(__xludf.DUMMYFUNCTION("""COMPUTED_VALUE"""),"Лесные ягоды") -> Лесные ягоды | B4: =IFERROR(__xludf.DUMMYFUNCTION("""COMPUTED_VALUE"""),"Алоэ виноград ") -> Алоэ виноград | C4: =IFERROR(__xludf.DUMMYFUNCTION("""COMPUTED_VALUE"""),"Апельсиновый адреналин") -> Апельсиновый адреналин | D4: =IFERROR(__xludf.DUMMYFUNCTION("""COMPUTED_VALUE"""),"Клюква лайм") -> Клюква лайм | E4: =IFERROR(__xludf.DUMMYFUNCTION("""COMPUTED_VALUE"""),"Виноградная фанта ") -> Виноградная фанта | F4: =IFERROR(__xludf.DUMMYFUNCTION("""COMPUTED_VALUE"""),"Зеленый чай лемонграсс") -> Зеленый чай лемонграсс | G4: =IFERROR(__xludf.DUMMYFUNCTION("""COMPUTED_VALUE"""),"Малина арбуз") -> Малина арбуз | H4: =IFERROR(__xludf.DUMMYFUNCTION("""COMPUTED_VALUE"""),"Ананас персик") -> Ананас персик | I4: =IFERROR(__xludf.DUMMYFUNCTION("""COMPUTED_VALUE"""),"Клубничный мохито ") -> Клубничный мохито | J4: =IFERROR(__xludf.DUMMYFUNCTION("""COMPUTED_VALUE"""),"Яблоко лайм") -> Яблоко лайм | K4: =IFERROR(__xludf.DUMMYFUNCTION("""COMPUTED_VALUE"""),"Спрайт арбуз лайм ") -> Спрайт арбуз лайм | L4: =IFERROR(__xludf.DUMMYFUNCTION("""COMPUTED_VALUE"""),"Черничная фанта") -> Черничная фанта | M4: =IFERROR(__xludf.DUMMYFUNCTION("""COMPUTED_VALUE"""),"Чёрная смородина") -> Чёрная смородина | N4: =IFERROR(__xludf.DUMMYFUNCTION("""COMPUTED_VALUE"""),"Червячки голубика малина") -> Червячки голубика малина | O4: =IFERROR(__xludf.DUMMYFUNCTION("""COMPUTED_VALUE"""),"Малина смородина ") -> Малина смородина | P4: =IFERROR(__xludf.DUMMYFUNCTION("""COMPUTED_VALUE"""),"Черника лайм ") -> Черника лайм | Q4: =IFERROR(__xludf.DUMMYFUNCTION("""COMPUTED_VALUE"""),"Виноградный чупа чупс") -> Виноградный чупа чупс | R4: =IFERROR(__xludf.DUMMYFUNCTION("""COMPUTED_VALUE"""),"Киви лайм") -> Киви лайм | S4: =IFERROR(__xludf.DUMMYFUNCTION("""COMPUTED_VALUE"""),"Ягодный морс") -> Ягодный морс | T4: =IFERROR(__xludf.DUMMYFUNCTION("""COMPUTED_VALUE"""),"Фруктовый скитлс") -> Фруктовый скитлс | U4: =IFERROR(__xludf.DUMMYFUNCTION("""COMPUTED_VALUE"""),"черника лимон ") -> черника лимон | V4: =IFERROR(__xludf.DUMMYFUNCTION("""COMPUTED_VALUE"""),"Вишнёвая бомба") -> Вишнёвая бомба | W4: =IFERROR(__xludf.DUMMYFUNCTION("""COMPUTED_VALUE"""),"Тропический манго") -> Тропический манго
A5: =IFERROR(__xludf.DUMMYFUNCTION("""COMPUTED_VALUE"""),"0.4") -> 0.4 | B5: =IFERROR(__xludf.DUMMYFUNCTION("""COMPUTED_VALUE"""),"0.6") -> 0.6 | C5: =IFERROR(__xludf.DUMMYFUNCTION("""COMPUTED_VALUE"""),"0.7") -> 0.7 | D5: =IFERROR(__xludf.DUMMYFUNCTION("""COMPUTED_VALUE"""),"0.8") -> 0.8
A6: =IFERROR(__xludf.DUMMYFUNCTION("""COMPUTED_VALUE"""),"0.4") -> 0.4 | B6: =IFERROR(__xludf.DUMMYFUNCTION("""COMPUTED_VALUE"""),"0.6") -> 0.6 | C6: =IFERROR(__xludf.DUMMYFUNCTION("""COMPUTED_VALUE"""),"0.7") -> 0.7 | D6: =IFERROR(__xludf.DUMMYFUNCTION("""COMPUTED_VALUE"""),"0.8") -> 0.8
A7: =IFERROR(__xludf.DUMMYFUNCTION("""COMPUTED_VALUE"""),"Малина вишня лёд") -> Малина вишня лёд
A8: =IFERROR(__xludf.DUMMYFUNCTION("""COMPUTED_VALUE"""),"кислая земляника") -> кислая земляника | B8: =IFERROR(__xludf.DUMMYFUNCTION("""COMPUTED_VALUE"""),"кислая фанта с черникой") -> кислая фанта с черникой | C8: =IFERROR(__xludf.DUMMYFUNCTION("""COMPUTED_VALUE"""),"кислое харибо с колой и черешней") -> кислое харибо с колой и черешней | D8: =IFERROR(__xludf.DUMMYFUNCTION("""COMPUTED_VALUE"""),"кислое яблочно клубничная шипучка") -> кислое яблочно клубничная шипучка | E8: =IFERROR(__xludf.DUMMYFUNCTION("""COMPUTED_VALUE"""),"кислые желатинки маракуйя ананас") -> кислые желатинки маракуйя ананас | F8: =IFERROR(__xludf.DUMMYFUNCTION("""COMPUTED_VALUE"""),"кислые ленточки маракуя манго") -> кислые ленточки маракуя манго | G8: =IFERROR(__xludf.DUMMYFUNCTION("""COMPUTED_VALUE"""),"кислые мармеладные ягоды") -> кислые мармеладные ягоды | H8: =IFERROR(__xludf.DUMMYFUNCTION("""COMPUTED_VALUE"""),"кислый виноград лайм") -> кислый виноград лайм | I8: =IFERROR(__xludf.DUMMYFUNCTION("""COMPUTED_VALUE"""),"кислый грейпфрут с вишней") -> кислый грейпфрут с вишней | J8: =IFERROR(__xludf.DUMMYFUNCTION("""COMPUTED_VALUE"""),"кислый леденец виноград киви яблоко") -> кислый леденец виноград киви яблоко | K8: =IFERROR(__xludf.DUMMYFUNCTION("""COMPUTED_VALUE"""),"кислый лимонад арбуз лайм малина") -> кислый лимонад арбуз лайм малина | L8: =IFERROR(__xludf.DUMMYFUNCTION("""COMPUTED_VALUE"""),"кислый персик клубника") -> кислый персик клубника | M8: =IFERROR(__xludf.DUMMYFUNCTION("""COMPUTED_VALUE"""),"кислый яблочно лимонные колечки") -> кислый яблочно лимонные колечки | N8: =IFERROR(__xludf.DUMMYFUNCTION("""COMPUTED_VALUE"""),"фанта апельсин с кислой малиной") -> фанта апельсин с кислой малиной
A9: =IFERROR(__xludf.DUMMYFUNCTION("""COMPUTED_VALUE"""),"0.4") -> 0.4 | B9: =IFERROR(__xludf.DUMMYFUNCTION("""COMPUTED_VALUE"""),"0.6") -> 0.6 | C9: =IFERROR(__xludf.DUMMYFUNCTION("""COMPUTED_VALUE"""),"0.7") -> 0.7 | D9: =IFERROR(__xludf.DUMMYFUNCTION("""COMPUTED_VALUE"""),"0.8") -> 0.8
A10: =IFERROR(__xludf.DUMMYFUNCTION("""COMPUTED_VALUE"""),"Арбуз Малина ") -> Арбуз Малина | B10: =IFERROR(__xludf.DUMMYFUNCTION("""COMPUTED_VALUE"""),"Банан Кокос ") -> Банан Кокос | C10: =IFERROR(__xludf.DUMMYFUNCTION("""COMPUTED_VALUE"""),"Барбарисовый Энергетик ") -> Барбарисовый Энергетик | D10: =IFERROR(__xludf.DUMMYFUNCTION("""COMPUTED_VALUE"""),"Виноградный Энергетик") -> Виноградный Энергетик | E10: =IFERROR(__xludf.DUMMYFUNCTION("""COMPUTED_VALUE"""),"Гранат Клубника ") -> Гранат Клубника | F10: =IFERROR(__xludf.DUMMYFUNCTION("""COMPUTED_VALUE"""),"Гранат Смородина ") -> Гранат Смородина | G10: =IFERROR(__xludf.DUMMYFUNCTION("""COMPUTED_VALUE"""),"Грейпфрутовый Швепс ") -> Грейпфрутовый Швепс | H10: =IFERROR(__xludf.DUMMYFUNCTION("""COMPUTED_VALUE"""),"Земляника Драгонфрут ") -> Земляника Драгонфрут | I10: =IFERROR(__xludf.DUMMYFUNCTION("""COMPUTED_VALUE"""),"Киви Личи ") -> Киви Личи | J10: =IFERROR(__xludf.DUMMYFUNCTION("""COMPUTED_VALUE"""),"Киви Маракуйя Гуава ") -> Киви Маракуйя Гуава | K10: =IFERROR(__xludf.DUMMYFUNCTION("""COMPUTED_VALUE"""),"Клубника Банан ") -> Клубника Банан | L10: =IFERROR(__xludf.DUMMYFUNCTION("""COMPUTED_VALUE"""),"Клубника Вишня ") -> Клубника Вишня | M10: =IFERROR(__xludf.DUMMYFUNCTION("""COMPUTED_VALUE"""),"Клубника Земляника ") -> Клубника Земляника | N10: =IFERROR(__xludf.DUMMYFUNCTION("""COMPUTED_VALUE"""),"Клубничный Мохито ") -> Клубничный Мохито | O10: =IFERROR(__xludf.DUMMYFUNCTION("""COMPUTED_VALUE"""),"Манго Грейпфрут ") -> Манго Грейпфрут | P10: =IFERROR(__xludf.DUMMYFUNCTION("""COMPUTED_VALUE"""),"Манго Персик Личи ") -> Манго Персик Личи | Q10: =IFERROR(__xludf.DUMMYFUNCTION("""COMPUTED_VALUE"""),"Персик Бабл Гам ") -> Персик Бабл Гам | R10: =IFERROR(__xludf.DUMMYFUNCTION("""COMPUTED_VALUE"""),"Садовые Ягоды ") -> Садовые Ягоды | S10: =IFERROR(__xludf.DUMMYFUNCTION("""COMPUTED_VALUE"""),"Скитлс Лимон Лайм 2") -> Скитлс Лимон Лайм 2 | T10: =IFERROR(__xludf.DUMMYFUNCTION("""COMPUTED_VALUE"""),"Смородина Мармелад 1") -> Смородина Мармелад 1 | U10: =IFERROR(__xludf.DUMMYFUNCTION("""COMPUTED_VALUE"""),"Темная Вишня 1") -> Темная Вишня 1 | V10: =IFERROR(__xludf.DUMMYFUNCTION("""COMPUTED_VALUE"""),"Фруктовые Пластинки 1") -> Фруктовые Пластинки 1 | W10: =IFERROR(__xludf.DUMMYFUNCTION("""COMPUTED_VALUE"""),"Черника Ежевика 1") -> Черника Ежевика 1 | X10: =IFERROR(__xludf.DUMMYFUNCTION("""COMPUTED_VALUE"""),"Черника Малина 1") -> Черника Малина 1 | Y10: =IFERROR(__xludf.DUMMYFUNCTION("""COMPUTED_VALUE"""),"Черника Мята 2") -> Черника Мята 2 | Z10: =IFERROR(__xludf.DUMMYFUNCTION("""COMPUTED_VALUE"""),"Яблоко Виноград 2") -> Яблоко Виноград 2 | AA10: =IFERROR(__xludf.DUMMYFUNCTION("""COMPUTED_VALUE"""),"Яблоко Малина 4") -> Яблоко Малина 4
A11: =IFERROR(__xludf.DUMMYFUNCTION("""COMPUTED_VALUE"""),"Арбуз Малина ") -> Арбуз Малина | B11: =IFERROR(__xludf.DUMMYFUNCTION("""COMPUTED_VALUE"""),"Банан Кокос ") -> Банан Кокос | C11: =IFERROR(__xludf.DUMMYFUNCTION("""COMPUTED_VALUE"""),"Барбарисовый Энергетик ") -> Барбарисовый Энергетик | D11: =IFERROR(__xludf.DUMMYFUNCTION("""COMPUTED_VALUE"""),"Виноградный Энергетик") -> Виноградный Энергетик | E11: =IFERROR(__xludf.DUMMYFUNCTION("""COMPUTED_VALUE"""),"Гранат Клубника ") -> Гранат Клубника | F11: =IFERROR(__xludf.DUMMYFUNCTION("""COMPUTED_VALUE"""),"Гранат Смородина ") -> Гранат Смородина | G11: =IFERROR(__xludf.DUMMYFUNCTION("""COMPUTED_VALUE"""),"Грейпфрутовый Швепс ") -> Грейпфрутовый Швепс | H11: =IFERROR(__xludf.DUMMYFUNCTION("""COMPUTED_VALUE"""),"Земляника Драгонфрут ") -> Земляника Драгонфрут | I11: =IFERROR(__xludf.DUMMYFUNCTION("""COMPUTED_VALUE"""),"Киви Личи ") -> Киви Личи | J11: =IFERROR(__xludf.DUMMYFUNCTION("""COMPUTED_VALUE"""),"Киви Маракуйя Гуава ") -> Киви Маракуйя Гуава | K11: =IFERROR(__xludf.DUMMYFUNCTION("""COMPUTED_VALUE"""),"Клубника Банан ") -> Клубника Банан | L11: =IFERROR(__xludf.DUMMYFUNCTION("""COMPUTED_VALUE"""),"Клубника Вишня ") -> Клубника Вишня | M11: =IFERROR(__xludf.DUMMYFUNCTION("""COMPUTED_VALUE"""),"Клубника Земляника ") -> Клубника Земляника | N11: =IFERROR(__xludf.DUMMYFUNCTION("""COMPUTED_VALUE"""),"Клубничный Мохито ") -> Клубничный Мохито | O11: =IFERROR(__xludf.DUMMYFUNCTION("""COMPUTED_VALUE"""),"Манго Грейпфрут ") -> Манго Грейпфрут | P11: =IFERROR(__xludf.DUMMYFUNCTION("""COMPUTED_VALUE"""),"Манго Персик Личи ") -> Манго Персик Личи | Q11: =IFERROR(__xludf.DUMMYFUNCTION("""COMPUTED_VALUE"""),"Персик Бабл Гам ") -> Персик Бабл Гам | R11: =IFERROR(__xludf.DUMMYFUNCTION("""COMPUTED_VALUE"""),"Садовые Ягоды ") -> Садовые Ягоды | S11: =IFERROR(__xludf.DUMMYFUNCTION("""COMPUTED_VALUE"""),"Скитлс Лимон Лайм 2") -> Скитлс Лимон Лайм 2 | T11: =IFERROR(__xludf.DUMMYFUNCTION("""COMPUTED_VALUE"""),"Смородина Мармелад 1") -> Смородина Мармелад 1 | U11: =IFERROR(__xludf.DUMMYFUNCTION("""COMPUTED_VALUE"""),"Темная Вишня 1") -> Темная Вишня 1 | V11: =IFERROR(__xludf.DUMMYFUNCTION("""COMPUTED_VALUE"""),"Фруктовые Пластинки 1") -> Фруктовые Пластинки 1 | W11: =IFERROR(__xludf.DUMMYFUNCTION("""COMPUTED_VALUE"""),"Черника Ежевика 1") -> Черника Ежевика 1 | X11: =IFERROR(__xludf.DUMMYFUNCTION("""COMPUTED_VALUE"""),"Черника Малина 1") -> Черника Малина 1 | Y11: =IFERROR(__xludf.DUMMYFUNCTION("""COMPUTED_VALUE"""),"Черника Мята 2") -> Черника Мята 2 | Z11: =IFERROR(__xludf.DUMMYFUNCTION("""COMPUTED_VALUE"""),"Яблоко Виноград 2") -> Яблоко Виноград 2 | AA11: =IFERROR(__xludf.DUMMYFUNCTION("""COMPUTED_VALUE"""),"Яблоко Малина 4") -> Яблоко Малина 4
A12: =IFERROR(__xludf.DUMMYFUNCTION("""COMPUTED_VALUE"""),"0.4") -> 0.4 | B12: =IFERROR(__xludf.DUMMYFUNCTION("""COMPUTED_VALUE"""),"0.6") -> 0.6 | C12: =IFERROR(__xludf.DUMMYFUNCTION("""COMPUTED_VALUE"""),"0.7") -> 0.7 | D12: =IFERROR(__xludf.DUMMYFUNCTION("""COMPUTED_VALUE"""),"0.8") -> 0.8
A13: =IFERROR(__xludf.DUMMYFUNCTION("""COMPUTED_VALUE"""),"0.4") -> 0.4 | B13: =IFERROR(__xludf.DUMMYFUNCTION("""COMPUTED_VALUE"""),"0.6") -> 0.6 | C13: =IFERROR(__xludf.DUMMYFUNCTION("""COMPUTED_VALUE"""),"0.7") -> 0.7 | D13: =IFERROR(__xludf.DUMMYFUNCTION("""COMPUTED_VALUE"""),"0.8") -> 0.8
A14: =IFERROR(__xludf.DUMMYFUNCTION("""COMPUTED_VALUE"""),"Маракуйя с тропическими нотками") -> Маракуйя с тропическими нотками | B14: =IFERROR(__xludf.DUMMYFUNCTION("""COMPUTED_VALUE"""),"Арбузный милкшейк") -> Арбузный милкшейк | C14: =IFERROR(__xludf.DUMMYFUNCTION("""COMPUTED_VALUE"""),"Конфеты со вкусом винограда") -> Конфеты со вкусом винограда | D14: =IFERROR(__xludf.DUMMYFUNCTION("""COMPUTED_VALUE"""),"Манго с апельсином и послевкусием гуавы") -> Манго с апельсином и послевкусием гуавы | E14: =IFERROR(__xludf.DUMMYFUNCTION("""COMPUTED_VALUE"""),"Холодное сочетание мяты и конфет холс") -> Холодное сочетание мяты и конфет холс | F14: =IFERROR(__xludf.DUMMYFUNCTION("""COMPUTED_VALUE"""),"Яблочные мармеладные червячки") -> Яблочные мармеладные червячки | G14: =IFERROR(__xludf.DUMMYFUNCTION("""COMPUTED_VALUE"""),"Микс сладкогоперсика и вишни с кислинкой") -> Микс сладкогоперсика и вишни с кислинкой | H14: =IFERROR(__xludf.DUMMYFUNCTION("""COMPUTED_VALUE"""),"Лимон лайм") -> Лимон лайм | I14: =IFERROR(__xludf.DUMMYFUNCTION("""COMPUTED_VALUE"""),"Классика энергетика с кислой малиной") -> Классика энергетика с кислой малиной | J14: =IFERROR(__xludf.DUMMYFUNCTION("""COMPUTED_VALUE"""),"Зеленое манго и смородина") -> Зеленое манго и смородина | K14: =IFERROR(__xludf.DUMMYFUNCTION("""COMPUTED_VALUE"""),"Дуэт лемонграсса и сладкой малины") -> Дуэт лемонграсса и сладкой малины | L14: =IFERROR(__xludf.DUMMYFUNCTION("""COMPUTED_VALUE"""),"Сладкий мармелад из черной смородины") -> Сладкий мармелад из черной смородины | M14: =IFERROR(__xludf.DUMMYFUNCTION("""COMPUTED_VALUE"""),"Вишня кола") -> Вишня кола | N14: =IFERROR(__xludf.DUMMYFUNCTION("""COMPUTED_VALUE"""),"Малина с кокосом") -> Малина с кокосом | O14: =IFERROR(__xludf.DUMMYFUNCTION("""COMPUTED_VALUE"""),"Сладкие конфеты СКИТЛЗ и смородина") -> Сладкие конфеты СКИТЛЗ и смородина | P14: =IFERROR(__xludf.DUMMYFUNCTION("""COMPUTED_VALUE"""),"Ежевичный лимонад") -> Ежевичный лимонад | Q14: =IFERROR(__xludf.DUMMYFUNCTION("""COMPUTED_VALUE"""),"Дыня кокос") -> Дыня кокос | R14: =IFERROR(__xludf.DUMMYFUNCTION("""COMPUTED_VALUE"""),"Земляничный бабл гам") -> Земляничный бабл гам | S14: =IFERROR(__xludf.DUMMYFUNCTION("""COMPUTED_VALUE"""),"Лимонные леденцы") -> Лимонные леденцы | T14: =IFERROR(__xludf.DUMMYFUNCTION("""COMPUTED_VALUE"""),"Экзотический фрукты") -> Экзотический фрукты | U14: =IFERROR(__xludf.DUMMYFUNCTION("""COMPUTED_VALUE"""),"Личи виноград мята") -> Личи виноград мята | V14: =IFERROR(__xludf.DUMMYFUNCTION("""COMPUTED_VALUE"""),"Черника малина мята") -> Черника малина мята | W14: =IFERROR(__xludf.DUMMYFUNCTION("""COMPUTED_VALUE"""),"Абрикосовый йогурт") -> Абрикосовый йогурт | X14: =IFERROR(__xludf.DUMMYFUNCTION("""COMPUTED_VALUE"""),"Арбуз лед") -> Арбуз лед | Y14: =IFERROR(__xludf.DUMMYFUNCTION("""COMPUTED_VALUE"""),"Банан клубника лед") -> Банан клубника лед | Z14: =IFERROR(__xludf.DUMMYFUNCTION("""COMPUTED_VALUE"""),"Арбузное мороженное") -> Арбузное мороженное | AA14: =IFERROR(__xludf.DUMMYFUNCTION("""COMPUTED_VALUE"""),"Клубника малина жвачка") -> Клубника малина жвачка | AB14: =IFERROR(__xludf.DUMMYFUNCTION("""COMPUTED_VALUE"""),"Клубничное мороженное") -> Клубничное мороженное | AC14: =IFERROR(__xludf.DUMMYFUNCTION("""COMPUTED_VALUE"""),"Кола сода лед") -> Кола сода лед | AD14: =IFERROR(__xludf.DUMMYFUNCTION("""COMPUTED_VALUE"""),"Банановый милкшейк") -> Банановый милкшейк | AE14: =IFERROR(__xludf.DUMMYFUNCTION("""COMPUTED_VALUE"""),"Микс ягод лед") -> Микс ягод лед | AF14: =IFERROR(__xludf.DUMMYFUNCTION("""COMPUTED_VALUE"""),"Брусничный морс") -> Брусничный морс | AG14: =IFERROR(__xludf.DUMMYFUNCTION("""COMPUTED_VALUE"""),"Яблочный лимонад") -> Яблочный лимонад | AH14: =IFERROR(__xludf.DUMMYFUNCTION("""COMPUTED_VALUE"""),"Лесные ягоды") -> Лесные ягоды | AI14: =IFERROR(__xludf.DUMMYFUNCTION("""COMPUTED_VALUE"""),"Смородиновый лимонад") -> Смородиновый лимонад | AJ14: =IFERROR(__xludf.DUMMYFUNCTION("""COMPUTED_VALUE"""),"Вишня лайм лед") -> Вишня лайм лед | AK14: =IFERROR(__xludf.DUMMYFUNCTION("""COMPUTED_VALUE"""),"Лист виноград мята энергетик") -> Лист виноград мята энергетик | AL14: =IFERROR(__xludf.DUMMYFUNCTION("""COMPUTED_VALUE"""),"Двойное яблоко лед") -> Двойное яблоко лед | AM14: =IFERROR(__xludf.DUMMYFUNCTION("""COMPUTED_VALUE"""),"Смородиновый холс") -> Смородиновый холс | AN14: =IFERROR(__xludf.DUMMYFUNCTION("""COMPUTED_VALUE"""),"Клубничное шампанское") -> Клубничное шампанское
A15: =IFERROR(__xludf.DUMMYFUNCTION("""COMPUTED_VALUE"""),"0.4") -> 0.4 | B15: =IFERROR(__xludf.DUMMYFUNCTION("""COMPUTED_VALUE"""),"0.6") -> 0.6 | C15: =IFERROR(__xludf.DUMMYFUNCTION("""COMPUTED_VALUE"""),"0.7") -> 0.7 | D15: =IFERROR(__xludf.DUMMYFUNCTION("""COMPUTED_VALUE"""),"0.8") -> 0.8
A16: =IFERROR(__xludf.DUMMYFUNCTION("""COMPUTED_VALUE"""),"кислая земляника") -> кислая земляника | B16: =IFERROR(__xludf.DUMMYFUNCTION("""COMPUTED_VALUE"""),"кислая фанта с черникой") -> кислая фанта с черникой | C16: =IFERROR(__xludf.DUMMYFUNCTION("""COMPUTED_VALUE"""),"кислое харибо с колой и черешней") -> кислое харибо с колой и черешней | D16: =IFERROR(__xludf.DUMMYFUNCTION("""COMPUTED_VALUE"""),"кислое яблочно клубничная шипучка") -> кислое яблочно клубничная шипучка | E16: =IFERROR(__xludf.DUMMYFUNCTION("""COMPUTED_VALUE"""),"кислые желатинки маракуйя ананас") -> кислые желатинки маракуйя ананас | F16: =IFERROR(__xludf.DUMMYFUNCTION("""COMPUTED_VALUE"""),"кислые ленточки маракуя манго") -> кислые ленточки маракуя манго | G16: =IFERROR(__xludf.DUMMYFUNCTION("""COMPUTED_VALUE"""),"кислые мармеладные ягоды") -> кислые мармеладные ягоды | H16: =IFERROR(__xludf.DUMMYFUNCTION("""COMPUTED_VALUE"""),"кислый виноград лайм") -> кислый виноград лайм | I16: =IFERROR(__xludf.DUMMYFUNCTION("""COMPUTED_VALUE"""),"кислый грейпфрут с вишней") -> кислый грейпфрут с вишней | J16: =IFERROR(__xludf.DUMMYFUNCTION("""COMPUTED_VALUE"""),"кислый леденец виноград киви яблоко") -> кислый леденец виноград киви яблоко | K16: =IFERROR(__xludf.DUMMYFUNCTION("""COMPUTED_VALUE"""),"кислый лимонад арбуз лайм малина") -> кислый лимонад арбуз лайм малина | L16: =IFERROR(__xludf.DUMMYFUNCTION("""COMPUTED_VALUE"""),"кислый персик клубника") -> кислый персик клубника | M16: =IFERROR(__xludf.DUMMYFUNCTION("""COMPUTED_VALUE"""),"кислый яблочно лимонные колечки") -> кислый яблочно лимонные колечки | N16: =IFERROR(__xludf.DUMMYFUNCTION("""COMPUTED_VALUE"""),"фанта апельсин с кислой малиной") -> фанта апельсин с кислой малиной
A17: =IFERROR(__xludf.DUMMYFUNCTION("""COMPUTED_VALUE"""),"0.4") -> 0.4 | B17: =IFERROR(__xludf.DUMMYFUNCTION("""COMPUTED_VALUE"""),"0.6") -> 0.6 | C17: =IFERROR(__xludf.DUMMYFUNCTION("""COMPUTED_VALUE"""),"0.7") -> 0.7 | D17: =IFERROR(__xludf.DUMMYFUNCTION("""COMPUTED_VALUE"""),"0.8") -> 0.8
A18: =IFERROR(__xludf.DUMMYFUNCTION("""COMPUTED_VALUE"""),"0.4") -> 0.4 | B18: =IFERROR(__xludf.DUMMYFUNCTION("""COMPUTED_VALUE"""),"0.6") -> 0.6 | C18: =IFERROR(__xludf.DUMMYFUNCTION("""COMPUTED_VALUE"""),"0.7") -> 0.7 | D18: =IFERROR(__xludf.DUMMYFUNCTION("""COMPUTED_VALUE"""),"0.8") -> 0.8
A19: =IFERROR(__xludf.DUMMYFUNCTION("""COMPUTED_VALUE"""),"Ананас киви") -> Ананас киви | B19: =IFERROR(__xludf.DUMMYFUNCTION("""COMPUTED_VALUE"""),"Арбузный смузи") -> Арбузный смузи | C19: =IFERROR(__xludf.DUMMYFUNCTION("""COMPUTED_VALUE"""),"Виноградная фанта") -> Виноградная фанта | D19: =IFERROR(__xludf.DUMMYFUNCTION("""COMPUTED_VALUE"""),"Вишневый морс") -> Вишневый морс | E19: =IFERROR(__xludf.DUMMYFUNCTION("""COMPUTED_VALUE"""),"Гранатовый мармелад") -> Гранатовый мармелад | F19: =IFERROR(__xludf.DUMMYFUNCTION("""COMPUTED_VALUE"""),"Грейпфрут киви") -> Грейпфрут киви | G19: =IFERROR(__xludf.DUMMYFUNCTION("""COMPUTED_VALUE"""),"Ежевика мята") -> Ежевика мята | H19: =IFERROR(__xludf.DUMMYFUNCTION("""COMPUTED_VALUE"""),"Киви манго") -> Киви манго | I19: =IFERROR(__xludf.DUMMYFUNCTION("""COMPUTED_VALUE"""),"Клубника манго") -> Клубника манго | J19: =IFERROR(__xludf.DUMMYFUNCTION("""COMPUTED_VALUE"""),"черника грейфрут ") -> черника грейфрут | K19: =IFERROR(__xludf.DUMMYFUNCTION("""COMPUTED_VALUE"""),"Малина лайм") -> Малина лайм | L19: =IFERROR(__xludf.DUMMYFUNCTION("""COMPUTED_VALUE"""),"Манго арбуз ") -> Манго арбуз | M19: =IFERROR(__xludf.DUMMYFUNCTION("""COMPUTED_VALUE"""),"Малиновый чай с жасмином") -> Малиновый чай с жасмином | N19: =IFERROR(__xludf.DUMMYFUNCTION("""COMPUTED_VALUE"""),"малина апельсин ") -> малина апельсин | O19: =IFERROR(__xludf.DUMMYFUNCTION("""COMPUTED_VALUE"""),"Манго апельсин") -> Манго апельсин | P19: =IFERROR(__xludf.DUMMYFUNCTION("""COMPUTED_VALUE"""),"Ред булл") -> Ред булл | Q19: =IFERROR(__xludf.DUMMYFUNCTION("""COMPUTED_VALUE"""),"Спрайт") -> Спрайт | R19: =IFERROR(__xludf.DUMMYFUNCTION("""COMPUTED_VALUE"""),"ананас клюква ") -> ананас клюква | S19: =IFERROR(__xludf.DUMMYFUNCTION("""COMPUTED_VALUE"""),"Тархун") -> Тархун | T19: =IFERROR(__xludf.DUMMYFUNCTION("""COMPUTED_VALUE"""),"алоэ Виноград ") -> алоэ Виноград | U19: =IFERROR(__xludf.DUMMYFUNCTION("""COMPUTED_VALUE"""),"Фруктовая жвачка") -> Фруктовая жвачка | V19: =IFERROR(__xludf.DUMMYFUNCTION("""COMPUTED_VALUE"""),"Холодная кола") -> Холодная кола | W19: =IFERROR(__xludf.DUMMYFUNCTION("""COMPUTED_VALUE"""),"Черная смородина клюква") -> Черная смородина клюква | X19: =IFERROR(__xludf.DUMMYFUNCTION("""COMPUTED_VALUE"""),"Черника арбуз") -> Черника арбуз | Y19: =IFERROR(__xludf.DUMMYFUNCTION("""COMPUTED_VALUE"""),"Яблоко черника") -> Яблоко черника
A20: =IFERROR(__xludf.DUMMYFUNCTION("""COMPUTED_VALUE"""),"Арбуз Малина ") -> Арбуз Малина | B20: =IFERROR(__xludf.DUMMYFUNCTION("""COMPUTED_VALUE"""),"Банан Кокос ") -> Банан Кокос | C20: =IFERROR(__xludf.DUMMYFUNCTION("""COMPUTED_VALUE"""),"Барбарисовый Энергетик ") -> Барбарисовый Энергетик | D20: =IFERROR(__xludf.DUMMYFUNCTION("""COMPUTED_VALUE"""),"Виноградный Энергетик") -> Виноградный Энергетик | E20: =IFERROR(__xludf.DUMMYFUNCTION("""COMPUTED_VALUE"""),"Гранат Клубника ") -> Гранат Клубника | F20: =IFERROR(__xludf.DUMMYFUNCTION("""COMPUTED_VALUE"""),"Гранат Смородина ") -> Гранат Смородина | G20: =IFERROR(__xludf.DUMMYFUNCTION("""COMPUTED_VALUE"""),"Грейпфрутовый Швепс ") -> Грейпфрутовый Швепс | H20: =IFERROR(__xludf.DUMMYFUNCTION("""COMPUTED_VALUE"""),"Земляника Драгонфрут ") -> Земляника Драгонфрут | I20: =IFERROR(__xludf.DUMMYFUNCTION("""COMPUTED_VALUE"""),"Киви Личи ") -> Киви Личи | J20: =IFERROR(__xludf.DUMMYFUNCTION("""COMPUTED_VALUE"""),"Киви Маракуйя Гуава ") -> Киви Маракуйя Гуава | K20: =IFERROR(__xludf.DUMMYFUNCTION("""COMPUTED_VALUE"""),"Клубника Банан ") -> Клубника Банан | L20: =IFERROR(__xludf.DUMMYFUNCTION("""COMPUTED_VALUE"""),"Клубника Вишня ") -> Клубника Вишня | M20: =IFERROR(__xludf.DUMMYFUNCTION("""COMPUTED_VALUE"""),"Клубника Земляника ") -> Клубника Земляника | N20: =IFERROR(__xludf.DUMMYFUNCTION("""COMPUTED_VALUE"""),"Клубничный Мохито ") -> Клубничный Мохито | O20: =IFERROR(__xludf.DUMMYFUNCTION("""COMPUTED_VALUE"""),"Манго Грейпфрут ") -> Манго Грейпфрут | P20: =IFERROR(__xludf.DUMMYFUNCTION("""COMPUTED_VALUE"""),"Манго Персик Личи ") -> Манго Персик Личи | Q20: =IFERROR(__xludf.DUMMYFUNCTION("""COMPUTED_VALUE"""),"Персик Бабл Гам ") -> Персик Бабл Гам | R20: =IFERROR(__xludf.DUMMYFUNCTION("""COMPUTED_VALUE"""),"Садовые Ягоды ") -> Садовые Ягоды | S20: =IFERROR(__xludf.DUMMYFUNCTION("""COMPUTED_VALUE"""),"Скитлс Лимон Лайм 2") -> Скитлс Лимон Лайм 2 | T20: =IFERROR(__xludf.DUMMYFUNCTION("""COMPUTED_VALUE"""),"Смородина Мармелад 1") -> Смородина Мармелад 1 | U20: =IFERROR(__xludf.DUMMYFUNCTION("""COMPUTED_VALUE"""),"Темная Вишня 1") -> Темная Вишня 1 | V20: =IFERROR(__xludf.DUMMYFUNCTION("""COMPUTED_VALUE"""),"Фруктовые Пластинки 1") -> Фруктовые Пластинки 1 | W20: =IFERROR(__xludf.DUMMYFUNCTION("""COMPUTED_VALUE"""),"Черника Ежевика 1") -> Черника Ежевика 1 | X20: =IFERROR(__xludf.DUMMYFUNCTION("""COMPUTED_VALUE"""),"Черника Малина 1") -> Черника Малина 1 | Y20: =IFERROR(__xludf.DUMMYFUNCTION("""COMPUTED_VALUE"""),"Черника Мята 2") -> Черника Мята 2 | Z20: =IFERROR(__xludf.DUMMYFUNCTION("""COMPUTED_VALUE"""),"Яблоко Виноград 2") -> Яблоко Виноград 2 | AA20: =IFERROR(__xludf.DUMMYFUNCTION("""COMPUTED_VALUE"""),"Яблоко Малина 4") -> Яблоко Малина 4
A21: =IFERROR(__xludf.DUMMYFUNCTION("""COMPUTED_VALUE"""),"Апельсиновое драже") -> Апельсиновое драже | B21: =IFERROR(__xludf.DUMMYFUNCTION("""COMPUTED_VALUE"""),"Бабл гам") -> Бабл гам | C21: =IFERROR(__xludf.DUMMYFUNCTION("""COMPUTED_VALUE"""),"Виноградная конфета") -> Виноградная конфета | D21: =IFERROR(__xludf.DUMMYFUNCTION("""COMPUTED_VALUE"""),"Даня кокос") -> Даня кокос | E21: =IFERROR(__xludf.DUMMYFUNCTION("""COMPUTED_VALUE"""),"Земляника груша") -> Земляника груша | F21: =IFERROR(__xludf.DUMMYFUNCTION("""COMPUTED_VALUE"""),"Кислый киви") -> Кислый киви | G21: =IFERROR(__xludf.DUMMYFUNCTION("""COMPUTED_VALUE"""),"Кислый малиновый лимонад ") -> Кислый малиновый лимонад | H21: =IFERROR(__xludf.DUMMYFUNCTION("""COMPUTED_VALUE"""),"Кола сода айс") -> Кола сода айс | I21: =IFERROR(__xludf.DUMMYFUNCTION("""COMPUTED_VALUE"""),"Ледяной ананас") -> Ледяной ананас | J21: =IFERROR(__xludf.DUMMYFUNCTION("""COMPUTED_VALUE"""),"Лимонные червячки ") -> Лимонные червячки | K21: =IFERROR(__xludf.DUMMYFUNCTION("""COMPUTED_VALUE"""),"Манго апельсин") -> Манго апельсин | L21: =IFERROR(__xludf.DUMMYFUNCTION("""COMPUTED_VALUE"""),"Смородина виноград") -> Смородина виноград | M21: =IFERROR(__xludf.DUMMYFUNCTION("""COMPUTED_VALUE"""),"Яблочный холс") -> Яблочный холс | N21: =IFERROR(__xludf.DUMMYFUNCTION("""COMPUTED_VALUE"""),"Ягодный смузи") -> Ягодный смузи | O21: =IFERROR(__xludf.DUMMYFUNCTION("""COMPUTED_VALUE"""),"Ягодный энергетик") -> Ягодный энергетик
A22: =IFERROR(__xludf.DUMMYFUNCTION("""COMPUTED_VALUE"""),"Арбуз Малина ") -> Арбуз Малина | B22: =IFERROR(__xludf.DUMMYFUNCTION("""COMPUTED_VALUE"""),"Банан Кокос ") -> Банан Кокос | C22: =IFERROR(__xludf.DUMMYFUNCTION("""COMPUTED_VALUE"""),"Барбарисовый Энергетик ") -> Барбарисовый Энергетик | D22: =IFERROR(__xludf.DUMMYFUNCTION("""COMPUTED_VALUE"""),"Виноградный Энергетик") -> Виноградный Энергетик | E22: =IFERROR(__xludf.DUMMYFUNCTION("""COMPUTED_VALUE"""),"Гранат Клубника ") -> Гранат Клубника | F22: =IFERROR(__xludf.DUMMYFUNCTION("""COMPUTED_VALUE"""),"Гранат Смородина ") -> Гранат Смородина | G22: =IFERROR(__xludf.DUMMYFUNCTION("""COMPUTED_VALUE"""),"Грейпфрутовый Швепс ") -> Грейпфрутовый Швепс | H22: =IFERROR(__xludf.DUMMYFUNCTION("""COMPUTED_VALUE"""),"Земляника Драгонфрут ") -> Земляника Драгонфрут | I22: =IFERROR(__xludf.DUMMYFUNCTION("""COMPUTED_VALUE"""),"Киви Личи ") -> Киви Личи | J22: =IFERROR(__xludf.DUMMYFUNCTION("""COMPUTED_VALUE"""),"Киви Маракуйя Гуава ") -> Киви Маракуйя Гуава | K22: =IFERROR(__xludf.DUMMYFUNCTION("""COMPUTED_VALUE"""),"Клубника Банан ") -> Клубника Банан | L22: =IFERROR(__xludf.DUMMYFUNCTION("""COMPUTED_VALUE"""),"Клубника Вишня ") -> Клубника Вишня | M22: =IFERROR(__xludf.DUMMYFUNCTION("""COMPUTED_VALUE"""),"Клубника Земляника ") -> Клубника Земляника | N22: =IFERROR(__xludf.DUMMYFUNCTION("""COMPUTED_VALUE"""),"Клубничный Мохито ") -> Клубничный Мохито | O22: =IFERROR(__xludf.DUMMYFUNCTION("""COMPUTED_VALUE"""),"Манго Грейпфрут ") -> Манго Грейпфрут | P22: =IFERROR(__xludf.DUMMYFUNCTION("""COMPUTED_VALUE"""),"Манго Персик Личи ") -> Манго Персик Личи | Q22: =IFERROR(__xludf.DUMMYFUNCTION("""COMPUTED_VALUE"""),"Персик Бабл Гам ") -> Персик Бабл Гам | R22: =IFERROR(__xludf.DUMMYFUNCTION("""COMPUTED_VALUE"""),"Садовые Ягоды ") -> Садовые Ягоды | S22: =IFERROR(__xludf.DUMMYFUNCTION("""COMPUTED_VALUE"""),"Скитлс Лимон Лайм 2") -> Скитлс Лимон Лайм 2 | T22: =IFERROR(__xludf.DUMMYFUNCTION("""COMPUTED_VALUE"""),"Смородина Мармелад 1") -> Смородина Мармелад 1 | U22: =IFERROR(__xludf.DUMMYFUNCTION("""COMPUTED_VALUE"""),"Темная Вишня 1") -> Темная Вишня 1 | V22: =IFERROR(__xludf.DUMMYFUNCTION("""COMPUTED_VALUE"""),"Фруктовые Пластинки 1") -> Фруктовые Пластинки 1 | W22: =IFERROR(__xludf.DUMMYFUNCTION("""COMPUTED_VALUE"""),"Черника Ежевика 1") -> Черника Ежевика 1 | X22: =IFERROR(__xludf.DUMMYFUNCTION("""COMPUTED_VALUE"""),"Черника Малина 1") -> Черника Малина 1 | Y22: =IFERROR(__xludf.DUMMYFUNCTION("""COMPUTED_VALUE"""),"Черника Мята 2") -> Черника Мята 2 | Z22: =IFERROR(__xludf.DUMMYFUNCTION("""COMPUTED_VALUE"""),"Яблоко Виноград 2") -> Яблоко Виноград 2 | AA22: =IFERROR(__xludf.DUMMYFUNCTION("""COMPUTED_VALUE"""),"Яблоко Малина 4") -> Яблоко Малина 4
A23: =IFERROR(__xludf.DUMMYFUNCTION("""COMPUTED_VALUE"""),"0.4") -> 0.4 | B23: =IFERROR(__xludf.DUMMYFUNCTION("""COMPUTED_VALUE"""),"0.6") -> 0.6 | C23: =IFERROR(__xludf.DUMMYFUNCTION("""COMPUTED_VALUE"""),"0.7") -> 0.7 | D23: =IFERROR(__xludf.DUMMYFUNCTION("""COMPUTED_VALUE"""),"0.8") -> 0.8
A24: =IFERROR(__xludf.DUMMYFUNCTION("""COMPUTED_VALUE"""),"0.2") -> 0.2 | B24: =IFERROR(__xludf.DUMMYFUNCTION("""COMPUTED_VALUE"""),"0.3") -> 0.3
A25: =IFERROR(__xludf.DUMMYFUNCTION("""COMPUTED_VALUE"""),"Ягодный микс") -> Ягодный микс | B25: =IFERROR(__xludf.DUMMYFUNCTION("""COMPUTED_VALUE"""),"Энергетик малина") -> Энергетик малина | C25: =IFERROR(__xludf.DUMMYFUNCTION("""COMPUTED_VALUE"""),"Клубника арбуз") -> Клубника арбуз | D25: =IFERROR(__xludf.DUMMYFUNCTION("""COMPUTED_VALUE"""),"Ежевика малина") -> Ежевика малина | E25: =IFERROR(__xludf.DUMMYFUNCTION("""COMPUTED_VALUE"""),"Голубая малина виноград") -> Голубая малина виноград | F25: =IFERROR(__xludf.DUMMYFUNCTION("""COMPUTED_VALUE"""),"Вишня яблоко") -> Вишня яблоко | G25: =IFERROR(__xludf.DUMMYFUNCTION("""COMPUTED_VALUE"""),"Виноград лёд") -> Виноград лёд | H25: =IFERROR(__xludf.DUMMYFUNCTION("""COMPUTED_VALUE"""),"Бабл гам") -> Бабл гам | I25: =IFERROR(__xludf.DUMMYFUNCTION("""COMPUTED_VALUE"""),"Энергетик лайм") -> Энергетик лайм | J25: =IFERROR(__xludf.DUMMYFUNCTION("""COMPUTED_VALUE"""),"Черника смородина айс") -> Черника смородина айс | K25: =IFERROR(__xludf.DUMMYFUNCTION("""COMPUTED_VALUE"""),"Мохито клубничный лёд") -> Мохито клубничный лёд | L25: =IFERROR(__xludf.DUMMYFUNCTION("""COMPUTED_VALUE"""),"Черная вишня лёд") -> Черная вишня лёд | M25: =IFERROR(__xludf.DUMMYFUNCTION("""COMPUTED_VALUE"""),"Ананас кокос лёд") -> Ананас кокос лёд | N25: =IFERROR(__xludf.DUMMYFUNCTION("""COMPUTED_VALUE"""),"Киви лёд") -> Киви лёд | O25: =IFERROR(__xludf.DUMMYFUNCTION("""COMPUTED_VALUE"""),"Кислая клюква лёд") -> Кислая клюква лёд | P25: =IFERROR(__xludf.DUMMYFUNCTION("""COMPUTED_VALUE"""),"Кислый скитлс лёд") -> Кислый скитлс лёд | Q25: =IFERROR(__xludf.DUMMYFUNCTION("""COMPUTED_VALUE"""),"Клубника черника лёд") -> Клубника черника лёд | R25: =IFERROR(__xludf.DUMMYFUNCTION("""COMPUTED_VALUE"""),"Малина смородина лёд") -> Малина смородина лёд | S25: =IFERROR(__xludf.DUMMYFUNCTION("""COMPUTED_VALUE"""),"Манго лёд") -> Манго лёд | T25: =IFERROR(__xludf.DUMMYFUNCTION("""COMPUTED_VALUE"""),"Малина вишня лёд") -> Малина вишня лёд
A26: =IFERROR(__xludf.DUMMYFUNCTION("""COMPUTED_VALUE"""),"Арбуз Малина ") -> Арбуз Малина | B26: =IFERROR(__xludf.DUMMYFUNCTION("""COMPUTED_VALUE"""),"Банан Кокос ") -> Банан Кокос | C26: =IFERROR(__xludf.DUMMYFUNCTION("""COMPUTED_VALUE"""),"Барбарисовый Энергетик ") -> Барбарисовый Энергетик | D26: =IFERROR(__xludf.DUMMYFUNCTION("""COMPUTED_VALUE"""),"Виноградный Энергетик") -> Виноградный Энергетик | E26: =IFERROR(__xludf.DUMMYFUNCTION("""COMPUTED_VALUE"""),"Гранат Клубника ") -> Гранат Клубника | F26: =IFERROR(__xludf.DUMMYFUNCTION("""COMPUTED_VALUE"""),"Гранат Смородина ") -> Гранат Смородина | G26: =IFERROR(__xludf.DUMMYFUNCTION("""COMPUTED_VALUE"""),"Грейпфрутовый Швепс ") -> Грейпфрутовый Швепс | H26: =IFERROR(__xludf.DUMMYFUNCTION("""COMPUTED_VALUE"""),"Земляника Драгонфрут ") -> Земляника Драгонфрут | I26: =IFERROR(__xludf.DUMMYFUNCTION("""COMPUTED_VALUE"""),"Киви Личи ") -> Киви Личи | J26: =IFERROR(__xludf.DUMMYFUNCTION("""COMPUTED_VALUE"""),"Киви Маракуйя Гуава ") -> Киви Маракуйя Гуава | K26: =IFERROR(__xludf.DUMMYFUNCTION("""COMPUTED_VALUE"""),"Клубника Банан ") -> Клубника Банан | L26: =IFERROR(__xludf.DUMMYFUNCTION("""COMPUTED_VALUE"""),"Клубника Вишня ") -> Клубника Вишня | M26: =IFERROR(__xludf.DUMMYFUNCTION("""COMPUTED_VALUE"""),"Клубника Земляника ") -> Клубника Земляника | N26: =IFERROR(__xludf.DUMMYFUNCTION("""COMPUTED_VALUE"""),"Клубничный Мохито ") -> Клубничный Мохито | O26: =IFERROR(__xludf.DUMMYFUNCTION("""COMPUTED_VALUE"""),"Манго Грейпфрут ") -> Манго Грейпфрут | P26: =IFERROR(__xludf.DUMMYFUNCTION("""COMPUTED_VALUE"""),"Манго Персик Личи ") -> Манго Персик Личи | Q26: =IFERROR(__xludf.DUMMYFUNCTION("""COMPUTED_VALUE"""),"Персик Бабл Гам ") -> Персик Бабл Гам | R26: =IFERROR(__xludf.DUMMYFUNCTION("""COMPUTED_VALUE"""),"Садовые Ягоды ") -> Садовые Ягоды | S26: =IFERROR(__xludf.DUMMYFUNCTION("""COMPUTED_VALUE"""),"Скитлс Лимон Лайм 2") -> Скитлс Лимон Лайм 2 | T26: =IFERROR(__xludf.DUMMYFUNCTION("""COMPUTED_VALUE"""),"Смородина Мармелад 1") -> Смородина Мармелад 1 | U26: =IFERROR(__xludf.DUMMYFUNCTION("""COMPUTED_VALUE"""),"Темная Вишня 1") -> Темная Вишня 1 | V26: =IFERROR(__xludf.DUMMYFUNCTION("""COMPUTED_VALUE"""),"Фруктовые Пластинки 1") -> Фруктовые Пластинки 1 | W26: =IFERROR(__xludf.DUMMYFUNCTION("""COMPUTED_VALUE"""),"Черника Ежевика 1") -> Черника Ежевика 1 | X26: =IFERROR(__xludf.DUMMYFUNCTION("""COMPUTED_VALUE"""),"Черника Малина 1") -> Черника Малина 1 | Y26: =IFERROR(__xludf.DUMMYFUNCTION("""COMPUTED_VALUE"""),"Черника Мята 2") -> Черника Мята 2 | Z26: =IFERROR(__xludf.DUMMYFUNCTION("""COMPUTED_VALUE"""),"Яблоко Виноград 2") -> Яблоко Виноград 2 | AA26: =IFERROR(__xludf.DUMMYFUNCTION("""COMPUTED_VALUE"""),"Яблоко Малина 4") -> Яблоко Малина 4
A27: =IFERROR(__xludf.DUMMYFUNCTION("""COMPUTED_VALUE"""),"Арбуз Малина ") -> Арбуз Малина | B27: =IFERROR(__xludf.DUMMYFUNCTION("""COMPUTED_VALUE"""),"Банан Кокос ") -> Банан Кокос | C27: =IFERROR(__xludf.DUMMYFUNCTION("""COMPUTED_VALUE"""),"Барбарисовый Энергетик ") -> Барбарисовый Энергетик | D27: =IFERROR(__xludf.DUMMYFUNCTION("""COMPUTED_VALUE"""),"Виноградный Энергетик") -> Виноградный Энергетик | E27: =IFERROR(__xludf.DUMMYFUNCTION("""COMPUTED_VALUE"""),"Гранат Клубника ") -> Гранат Клубника | F27: =IFERROR(__xludf.DUMMYFUNCTION("""COMPUTED_VALUE"""),"Гранат Смородина ") -> Гранат Смородина | G27: =IFERROR(__xludf.DUMMYFUNCTION("""COMPUTED_VALUE"""),"Грейпфрутовый Швепс ") -> Грейпфрутовый Швепс | H27: =IFERROR(__xludf.DUMMYFUNCTION("""COMPUTED_VALUE"""),"Земляника Драгонфрут ") -> Земляника Драгонфрут | I27: =IFERROR(__xludf.DUMMYFUNCTION("""COMPUTED_VALUE"""),"Киви Личи ") -> Киви Личи | J27: =IFERROR(__xludf.DUMMYFUNCTION("""COMPUTED_VALUE"""),"Киви Маракуйя Гуава ") -> Киви Маракуйя Гуава | K27: =IFERROR(__xludf.DUMMYFUNCTION("""COMPUTED_VALUE"""),"Клубника Банан ") -> Клубника Банан | L27: =IFERROR(__xludf.DUMMYFUNCTION("""COMPUTED_VALUE"""),"Клубника Вишня ") -> Клубника Вишня | M27: =IFERROR(__xludf.DUMMYFUNCTION("""COMPUTED_VALUE"""),"Клубника Земляника ") -> Клубника Земляника | N27: =IFERROR(__xludf.DUMMYFUNCTION("""COMPUTED_VALUE"""),"Клубничный Мохито ") -> Клубничный Мохито | O27: =IFERROR(__xludf.DUMMYFUNCTION("""COMPUTED_VALUE"""),"Манго Грейпфрут ") -> Манго Грейпфрут | P27: =IFERROR(__xludf.DUMMYFUNCTION("""COMPUTED_VALUE"""),"Манго Персик Личи ") -> Манго Персик Личи | Q27: =IFERROR(__xludf.DUMMYFUNCTION("""COMPUTED_VALUE"""),"Персик Бабл Гам ") -> Персик Бабл Гам | R27: =IFERROR(__xludf.DUMMYFUNCTION("""COMPUTED_VALUE"""),"Садовые Ягоды ") -> Садовые Ягоды | S27: =IFERROR(__xludf.DUMMYFUNCTION("""COMPUTED_VALUE"""),"Скитлс Лимон Лайм 2") -> Скитлс Лимон Лайм 2 | T27: =IFERROR(__xludf.DUMMYFUNCTION("""COMPUTED_VALUE"""),"Смородина Мармелад 1") -> Смородина Мармелад 1 | U27: =IFERROR(__xludf.DUMMYFUNCTION("""COMPUTED_VALUE"""),"Темная Вишня 1") -> Темная Вишня 1 | V27: =IFERROR(__xludf.DUMMYFUNCTION("""COMPUTED_VALUE"""),"Фруктовые Пластинки 1") -> Фруктовые Пластинки 1 | W27: =IFERROR(__xludf.DUMMYFUNCTION("""COMPUTED_VALUE"""),"Черника Ежевика 1") -> Черника Ежевика 1 | X27: =IFERROR(__xludf.DUMMYFUNCTION("""COMPUTED_VALUE"""),"Черника Малина 1") -> Черника Малина 1 | Y27: =IFERROR(__xludf.DUMMYFUNCTION("""COMPUTED_VALUE"""),"Черника Мята 2") -> Черника Мята 2 | Z27: =IFERROR(__xludf.DUMMYFUNCTION("""COMPUTED_VALUE"""),"Яблоко Виноград 2") -> Яблоко Виноград 2 | AA27: =IFERROR(__xludf.DUMMYFUNCTION("""COMPUTED_VALUE"""),"Яблоко Малина 4") -> Яблоко Малина 4
A28: =IFERROR(__xludf.DUMMYFUNCTION("""COMPUTED_VALUE"""),"Ягодный микс") -> Ягодный микс | B28: =IFERROR(__xludf.DUMMYFUNCTION("""COMPUTED_VALUE"""),"Энергетик малина") -> Энергетик малина | C28: =IFERROR(__xludf.DUMMYFUNCTION("""COMPUTED_VALUE"""),"Клубника арбуз") -> Клубника арбуз | D28: =IFERROR(__xludf.DUMMYFUNCTION("""COMPUTED_VALUE"""),"Ежевика малина") -> Ежевика малина | E28: =IFERROR(__xludf.DUMMYFUNCTION("""COMPUTED_VALUE"""),"Голубая малина виноград") -> Голубая малина виноград | F28: =IFERROR(__xludf.DUMMYFUNCTION("""COMPUTED_VALUE"""),"Вишня яблоко") -> Вишня яблоко | G28: =IFERROR(__xludf.DUMMYFUNCTION("""COMPUTED_VALUE"""),"Виноград лёд") -> Виноград лёд | H28: =IFERROR(__xludf.DUMMYFUNCTION("""COMPUTED_VALUE"""),"Бабл гам") -> Бабл гам | I28: =IFERROR(__xludf.DUMMYFUNCTION("""COMPUTED_VALUE"""),"Энергетик лайм") -> Энергетик лайм | J28: =IFERROR(__xludf.DUMMYFUNCTION("""COMPUTED_VALUE"""),"Черника смородина айс") -> Черника смородина айс | K28: =IFERROR(__xludf.DUMMYFUNCTION("""COMPUTED_VALUE"""),"Мохито клубничный лёд") -> Мохито клубничный лёд | L28: =IFERROR(__xludf.DUMMYFUNCTION("""COMPUTED_VALUE"""),"Черная вишня лёд") -> Черная вишня лёд | M28: =IFERROR(__xludf.DUMMYFUNCTION("""COMPUTED_VALUE"""),"Ананас кокос лёд") -> Ананас кокос лёд | N28: =IFERROR(__xludf.DUMMYFUNCTION("""COMPUTED_VALUE"""),"Киви лёд") -> Киви лёд | O28: =IFERROR(__xludf.DUMMYFUNCTION("""COMPUTED_VALUE"""),"Кислая клюква лёд") -> Кислая клюква лёд | P28: =IFERROR(__xludf.DUMMYFUNCTION("""COMPUTED_VALUE"""),"Кислый скитлс лёд") -> Кислый скитлс лёд | Q28: =IFERROR(__xludf.DUMMYFUNCTION("""COMPUTED_VALUE"""),"Клубника черника лёд") -> Клубника черника лёд | R28: =IFERROR(__xludf.DUMMYFUNCTION("""COMPUTED_VALUE"""),"Малина смородина лёд") -> Малина смородина лёд | S28: =IFERROR(__xludf.DUMMYFUNCTION("""COMPUTED_VALUE"""),"Манго лёд") -> Манго лёд | T28: =IFERROR(__xludf.DUMMYFUNCTION("""COMPUTED_VALUE"""),"Малина вишня лёд") -> Малина вишня лёд
A29: =IFERROR(__xludf.DUMMYFUNCTION("""COMPUTED_VALUE"""),"Апельсиновое драже") -> Апельсиновое драже | B29: =IFERROR(__xludf.DUMMYFUNCTION("""COMPUTED_VALUE"""),"Бабл гам") -> Бабл гам | C29: =IFERROR(__xludf.DUMMYFUNCTION("""COMPUTED_VALUE"""),"Виноградная конфета") -> Виноградная конфета | D29: =IFERROR(__xludf.DUMMYFUNCTION("""COMPUTED_VALUE"""),"Даня кокос") -> Даня кокос | E29: =IFERROR(__xludf.DUMMYFUNCTION("""COMPUTED_VALUE"""),"Земляника груша") -> Земляника груша | F29: =IFERROR(__xludf.DUMMYFUNCTION("""COMPUTED_VALUE"""),"Кислый киви") -> Кислый киви | G29: =IFERROR(__xludf.DUMMYFUNCTION("""COMPUTED_VALUE"""),"Кислый малиновый лимонад ") -> Кислый малиновый лимонад | H29: =IFERROR(__xludf.DUMMYFUNCTION("""COMPUTED_VALUE"""),"Кола сода айс") -> Кола сода айс | I29: =IFERROR(__xludf.DUMMYFUNCTION("""COMPUTED_VALUE"""),"Ледяной ананас") -> Ледяной ананас | J29: =IFERROR(__xludf.DUMMYFUNCTION("""COMPUTED_VALUE"""),"Лимонные червячки ") -> Лимонные червячки | K29: =IFERROR(__xludf.DUMMYFUNCTION("""COMPUTED_VALUE"""),"Манго апельсин") -> Манго апельсин | L29: =IFERROR(__xludf.DUMMYFUNCTION("""COMPUTED_VALUE"""),"Смородина виноград") -> Смородина виноград | M29: =IFERROR(__xludf.DUMMYFUNCTION("""COMPUTED_VALUE"""),"Яблочный холс") -> Яблочный холс | N29: =IFERROR(__xludf.DUMMYFUNCTION("""COMPUTED_VALUE"""),"Ягодный смузи") -> Ягодный смузи | O29: =IFERROR(__xludf.DUMMYFUNCTION("""COMPUTED_VALUE"""),"Ягодный энергетик") -> Ягодный энергетик
A30: =IFERROR(__xludf.DUMMYFUNCTION("""COMPUTED_VALUE"""),"Лесные ягоды") -> Лесные ягоды | B30: =IFERROR(__xludf.DUMMYFUNCTION("""COMPUTED_VALUE"""),"Алоэ виноград ") -> Алоэ виноград | C30: =IFERROR(__xludf.DUMMYFUNCTION("""COMPUTED_VALUE"""),"Апельсиновый адреналин") -> Апельсиновый адреналин | D30: =IFERROR(__xludf.DUMMYFUNCTION("""COMPUTED_VALUE"""),"Клюква лайм") -> Клюква лайм | E30: =IFERROR(__xludf.DUMMYFUNCTION("""COMPUTED_VALUE"""),"Виноградная фанта ") -> Виноградная фанта | F30: =IFERROR(__xludf.DUMMYFUNCTION("""COMPUTED_VALUE"""),"Зеленый чай лемонграсс") -> Зеленый чай лемонграсс | G30: =IFERROR(__xludf.DUMMYFUNCTION("""COMPUTED_VALUE"""),"Малина арбуз") -> Малина арбуз | H30: =IFERROR(__xludf.DUMMYFUNCTION("""COMPUTED_VALUE"""),"Ананас персик") -> Ананас персик | I30: =IFERROR(__xludf.DUMMYFUNCTION("""COMPUTED_VALUE"""),"Клубничный мохито ") -> Клубничный мохито | J30: =IFERROR(__xludf.DUMMYFUNCTION("""COMPUTED_VALUE"""),"Яблоко лайм") -> Яблоко лайм | K30: =IFERROR(__xludf.DUMMYFUNCTION("""COMPUTED_VALUE"""),"Спрайт арбуз лайм ") -> Спрайт арбуз лайм | L30: =IFERROR(__xludf.DUMMYFUNCTION("""COMPUTED_VALUE"""),"Черничная фанта") -> Черничная фанта | M30: =IFERROR(__xludf.DUMMYFUNCTION("""COMPUTED_VALUE"""),"Чёрная смородина") -> Чёрная смородина | N30: =IFERROR(__xludf.DUMMYFUNCTION("""COMPUTED_VALUE"""),"Червячки голубика малина") -> Червячки голубика малина | O30: =IFERROR(__xludf.DUMMYFUNCTION("""COMPUTED_VALUE"""),"Малина смородина ") -> Малина смородина | P30: =IFERROR(__xludf.DUMMYFUNCTION("""COMPUTED_VALUE"""),"Черника лайм ") -> Черника лайм | Q30: =IFERROR(__xludf.DUMMYFUNCTION("""COMPUTED_VALUE"""),"Виноградный чупа чупс") -> Виноградный чупа чупс | R30: =IFERROR(__xludf.DUMMYFUNCTION("""COMPUTED_VALUE"""),"Киви лайм") -> Киви лайм | S30: =IFERROR(__xludf.DUMMYFUNCTION("""COMPUTED_VALUE"""),"Ягодный морс") -> Ягодный морс | T30: =IFERROR(__xludf.DUMMYFUNCTION("""COMPUTED_VALUE"""),"Фруктовый скитлс") -> Фруктовый скитлс | U30: =IFERROR(__xludf.DUMMYFUNCTION("""COMPUTED_VALUE"""),"черника лимон ") -> черника лимон | V30: =IFERROR(__xludf.DUMMYFUNCTION("""COMPUTED_VALUE"""),"Вишнёвая бомба") -> Вишнёвая бомба | W30: =IFERROR(__xludf.DUMMYFUNCTION("""COMPUTED_VALUE"""),"Тропический манго") -> Тропический манго
A31: =IFERROR(__xludf.DUMMYFUNCTION("""COMPUTED_VALUE"""),"Кислый малиново-грейпфрутовый швепс") -> Кислый малиново-грейпфрутовый швепс | B31: =IFERROR(__xludf.DUMMYFUNCTION("""COMPUTED_VALUE"""),"Ананас апельсин") -> Ананас апельсин | C31: =IFERROR(__xludf.DUMMYFUNCTION("""COMPUTED_VALUE"""),"Пинаколада") -> Пинаколада | D31: =IFERROR(__xludf.DUMMYFUNCTION("""COMPUTED_VALUE"""),"Мятный бабл гам") -> Мятный бабл гам | E31: =IFERROR(__xludf.DUMMYFUNCTION("""COMPUTED_VALUE"""),"Мянго драгонфрут") -> Мянго драгонфрут | F31: =IFERROR(__xludf.DUMMYFUNCTION("""COMPUTED_VALUE"""),"Клубничная фанта") -> Клубничная фанта | G31: =IFERROR(__xludf.DUMMYFUNCTION("""COMPUTED_VALUE"""),"Клубничная арбуз") -> Клубничная арбуз | H31: =IFERROR(__xludf.DUMMYFUNCTION("""COMPUTED_VALUE"""),"Кислый скитлс") -> Кислый скитлс | I31: =IFERROR(__xludf.DUMMYFUNCTION("""COMPUTED_VALUE"""),"Кислый лайм арбуз") -> Кислый лайм арбуз | J31: =IFERROR(__xludf.DUMMYFUNCTION("""COMPUTED_VALUE"""),"Тропический банан") -> Тропический банан | K31: =IFERROR(__xludf.DUMMYFUNCTION("""COMPUTED_VALUE"""),"Яблочный энергетик") -> Яблочный энергетик | L31: =IFERROR(__xludf.DUMMYFUNCTION("""COMPUTED_VALUE"""),"Барбарисовый лимонад") -> Барбарисовый лимонад | M31: =IFERROR(__xludf.DUMMYFUNCTION("""COMPUTED_VALUE"""),"Лимонад виноград вишня") -> Лимонад виноград вишня | N31: =IFERROR(__xludf.DUMMYFUNCTION("""COMPUTED_VALUE"""),"Розовый лимонад") -> Розовый лимонад | O31: =IFERROR(__xludf.DUMMYFUNCTION("""COMPUTED_VALUE"""),"Двойной манго") -> Двойной манго | P31: =IFERROR(__xludf.DUMMYFUNCTION("""COMPUTED_VALUE"""),"Лесные ягоды ") -> Лесные ягоды | Q31: =IFERROR(__xludf.DUMMYFUNCTION("""COMPUTED_VALUE"""),"Ежевика малина ") -> Ежевика малина | R31: =IFERROR(__xludf.DUMMYFUNCTION("""COMPUTED_VALUE"""),"Смородиновый лимонад") -> Смородиновый лимонад | S31: =IFERROR(__xludf.DUMMYFUNCTION("""COMPUTED_VALUE"""),"Кола вишня") -> Кола вишня | T31: =IFERROR(__xludf.DUMMYFUNCTION("""COMPUTED_VALUE"""),"Манго арбуз") -> Манго арбуз | U31: =IFERROR(__xludf.DUMMYFUNCTION("""COMPUTED_VALUE"""),"Алоэ виноград") -> Алоэ виноград | V31: =IFERROR(__xludf.DUMMYFUNCTION("""COMPUTED_VALUE"""),"Банан клубника") -> Банан клубника | W31: =IFERROR(__xludf.DUMMYFUNCTION("""COMPUTED_VALUE"""),"Малиновый мармелад") -> Малиновый мармелад | X31: =IFERROR(__xludf.DUMMYFUNCTION("""COMPUTED_VALUE"""),"Клубника киви") -> Клубника киви | Y31: =IFERROR(__xludf.DUMMYFUNCTION("""COMPUTED_VALUE"""),"Клюква лайм") -> Клюква лайм | Z31: =IFERROR(__xludf.DUMMYFUNCTION("""COMPUTED_VALUE"""),"Гуава ананас") -> Гуава ананас | AA31: =IFERROR(__xludf.DUMMYFUNCTION("""COMPUTED_VALUE"""),"Морс") -> Морс | AB31: =IFERROR(__xludf.DUMMYFUNCTION("""COMPUTED_VALUE"""),"Красный апельсин") -> Красный апельсин | AC31: =IFERROR(__xludf.DUMMYFUNCTION("""COMPUTED_VALUE"""),"Арбузная жвачка") -> Арбузная жвачка | AD31: =IFERROR(__xludf.DUMMYFUNCTION("""COMPUTED_VALUE"""),"Смородина Виноград") -> Смородина Виноград | AE31: =IFERROR(__xludf.DUMMYFUNCTION("""COMPUTED_VALUE"""),"Гранатовая Мармелад") -> Гранатовая Мармелад | AF31: =IFERROR(__xludf.DUMMYFUNCTION("""COMPUTED_VALUE"""),"Яблоко Киви") -> Яблоко Киви | AG31: =IFERROR(__xludf.DUMMYFUNCTION("""COMPUTED_VALUE"""),"Клубника Ежевика") -> Клубника Ежевика | AH31: =IFERROR(__xludf.DUMMYFUNCTION("""COMPUTED_VALUE"""),"Клубничный Коктейль") -> Клубничный Коктейль | AI31: =IFERROR(__xludf.DUMMYFUNCTION("""COMPUTED_VALUE"""),"Клюква Земляника ") -> Клюква Земляника | AJ31: =IFERROR(__xludf.DUMMYFUNCTION("""COMPUTED_VALUE"""),"Какос Дыня") -> Какос Дыня | AK31: =IFERROR(__xludf.DUMMYFUNCTION("""COMPUTED_VALUE"""),"Маракуйя мандарин") -> Маракуйя мандарин | AL31: =IFERROR(__xludf.DUMMYFUNCTION("""COMPUTED_VALUE"""),"Персик кактус") -> Персик кактус | AM31: =IFERROR(__xludf.DUMMYFUNCTION("""COMPUTED_VALUE"""),"Спрайт") -> Спрайт | AN31: =IFERROR(__xludf.DUMMYFUNCTION("""COMPUTED_VALUE"""),"Черничная фанта") -> Черничная фанта | AO31: =IFERROR(__xludf.DUMMYFUNCTION("""COMPUTED_VALUE"""),"Ягодная жвачка") -> Ягодная жвачка | AP31: =IFERROR(__xludf.DUMMYFUNCTION("""COMPUTED_VALUE"""),"Ягодный энергетик") -> Ягодный энергетик | AQ31: =IFERROR(__xludf.DUMMYFUNCTION("""COMPUTED_VALUE"""),"Ягодный пунш ") -> Ягодный пунш | AR31: =IFERROR(__xludf.DUMMYFUNCTION("""COMPUTED_VALUE"""),"Виноградный холс") -> Виноградный холс | AS31: =IFERROR(__xludf.DUMMYFUNCTION("""COMPUTED_VALUE"""),"Грейпфрут смородина") -> Грейпфрут смородина | AT31: =IFERROR(__xludf.DUMMYFUNCTION("""COMPUTED_VALUE"""),"Дыня персик") -> Дыня персик | AU31: =IFERROR(__xludf.DUMMYFUNCTION("""COMPUTED_VALUE"""),"Земляника виноград") -> Земляника виноград | AV31: =IFERROR(__xludf.DUMMYFUNCTION("""COMPUTED_VALUE"""),"Киви маракуйя гуава") -> Киви маракуйя гуава | AW31: =IFERROR(__xludf.DUMMYFUNCTION("""COMPUTED_VALUE"""),"Кислые вишнёвые червячки") -> Кислые вишнёвые червячки | AX31: =IFERROR(__xludf.DUMMYFUNCTION("""COMPUTED_VALUE"""),"Кислые чернично-малиновое червячки") -> Кислые чернично-малиновое червячки
A32: =IFERROR(__xludf.DUMMYFUNCTION("""COMPUTED_VALUE"""),"Ягодный микс") -> Ягодный микс | B32: =IFERROR(__xludf.DUMMYFUNCTION("""COMPUTED_VALUE"""),"Энергетик малина") -> Энергетик малина | C32: =IFERROR(__xludf.DUMMYFUNCTION("""COMPUTED_VALUE"""),"Клубника арбуз") -> Клубника арбуз | D32: =IFERROR(__xludf.DUMMYFUNCTION("""COMPUTED_VALUE"""),"Ежевика малина") -> Ежевика малина | E32: =IFERROR(__xludf.DUMMYFUNCTION("""COMPUTED_VALUE"""),"Голубая малина виноград") -> Голубая малина виноград | F32: =IFERROR(__xludf.DUMMYFUNCTION("""COMPUTED_VALUE"""),"Вишня яблоко") -> Вишня яблоко | G32: =IFERROR(__xludf.DUMMYFUNCTION("""COMPUTED_VALUE"""),"Виноград лёд") -> Виноград лёд | H32: =IFERROR(__xludf.DUMMYFUNCTION("""COMPUTED_VALUE"""),"Бабл гам") -> Бабл гам | I32: =IFERROR(__xludf.DUMMYFUNCTION("""COMPUTED_VALUE"""),"Энергетик лайм") -> Энергетик лайм | J32: =IFERROR(__xludf.DUMMYFUNCTION("""COMPUTED_VALUE"""),"Черника смородина айс") -> Черника смородина айс | K32: =IFERROR(__xludf.DUMMYFUNCTION("""COMPUTED_VALUE"""),"Мохито клубничный лёд") -> Мохито клубничный лёд | L32: =IFERROR(__xludf.DUMMYFUNCTION("""COMPUTED_VALUE"""),"Черная вишня лёд") -> Черная вишня лёд | M32: =IFERROR(__xludf.DUMMYFUNCTION("""COMPUTED_VALUE"""),"Ананас кокос лёд") -> Ананас кокос лёд | N32: =IFERROR(__xludf.DUMMYFUNCTION("""COMPUTED_VALUE"""),"Киви лёд") -> Киви лёд | O32: =IFERROR(__xludf.DUMMYFUNCTION("""COMPUTED_VALUE"""),"Кислая клюква лёд") -> Кислая клюква лёд | P32: =IFERROR(__xludf.DUMMYFUNCTION("""COMPUTED_VALUE"""),"Кислый скитлс лёд") -> Кислый скитлс лёд | Q32: =IFERROR(__xludf.DUMMYFUNCTION("""COMPUTED_VALUE"""),"Клубника черника лёд") -> Клубника черника лёд | R32: =IFERROR(__xludf.DUMMYFUNCTION("""COMPUTED_VALUE"""),"Малина смородина лёд") -> Малина смородина лёд | S32: =IFERROR(__xludf.DUMMYFUNCTION("""COMPUTED_VALUE"""),"Манго лёд") -> Манго лёд | T32: =IFERROR(__xludf.DUMMYFUNCTION("""COMPUTED_VALUE"""),"Малина вишня лёд") -> Малина вишня лёд
